<?xml version="1.0" encoding="utf-8"?>
<!-- =================================================================================== -->
<!-- |    This document was autogenerated by xacro from snake.xacro                    | -->
<!-- |    EDITING THIS FILE BY HAND IS NOT RECOMMENDED                                 | -->
<!-- =================================================================================== -->
<robot name="snake">
  <material name="blue">
    <color rgba="0 0 0.8 0.7"/>
  </material>
  <material name="green">
    <color rgba="0 0.8 0 0.7"/>
  </material>
  <link name="base">
    <visual>
      <geometry>
        <box size="10 5 4"/>
      </geometry>
      <material name="green"/>
    </visual>
  </link>
  <joint name="body1_to_base" type="revolute">
    <parent link="base"/>
    <child link="body1"/>
    <origin rpy="0 0 0" xyz="9.5 0 0"/>
    <axis xyz="0 1 0"/>
    <limit effort="100" lower="-1.0471975512" upper="1.0471975512" velocity="5"/>
  </joint>
  <link name="body1">
    <visual>
      <geometry>
        <box size="7.6 4.7 2.4"/>
      </geometry>
      <origin rpy="0 0 0" xyz="7.1 0 0"/>
      <material name="blue"/>
    </visual>
  </link>
  <joint name="body2_to_body1" type="revolute">
    <parent link="body1"/>
    <child link="body2"/>
    <origin rpy="0 0 0" xyz="14.2 0 0"/>
    <axis xyz="0 0 1"/>
    <limit effort="100" lower="-0.785398163397" upper="0.785398163397" velocity="5"/>
  </joint>
  <link name="body2">
    <visual>
      <geometry>
        <box size="7.6 4.7 2.4"/>
      </geometry>
      <origin rpy="0 0 0" xyz="7.1 0 0"/>
      <material name="blue"/>
    </visual>
  </link>
  <joint name="body3_to_body2" type="revolute">
    <parent link="body2"/>
    <child link="body3"/>
    <origin rpy="0 0 0" xyz="14.2 0 0"/>
    <axis xyz="0 1 0"/>
    <limit effort="100" lower="-1.57079632679" upper="1.57079632679" velocity="5"/>
  </joint>
  <link name="body3">
    <visual>
      <geometry>
        <box size="7.6 4.7 2.4"/>
      </geometry>
      <origin rpy="0 0 0" xyz="7.1 0 0"/>
      <material name="blue"/>
    </visual>
  </link>
</robot>

