<?xml version="1.0" ?>
<!-- =================================================================================== -->
<!-- |    This document was autogenerated by xacro from snake.xacro                    | -->
<!-- |    EDITING THIS FILE BY HAND IS NOT RECOMMENDED                                 | -->
<!-- =================================================================================== -->
<robot name="snake">
  <material name="blue">
    <color rgba="0 0 0.8 0.7"/>
  </material>
  <material name="green">
    <color rgba="0 0.8 0 0.7"/>
  </material>
  <link name="base">
    <visual>
      <geometry>
        <box size="7.5 5 2.8"/>
      </geometry>
      <material name="green"/>
    </visual>
  </link>
  <!-- First chain -->
  <joint name="body1_to_base" type="revolute">
    <parent link="base"/>
    <child link="body1"/>
    <origin rpy="0 0 0" xyz="7.0 0 0"/>
    <axis xyz="0 1 0"/>
    <limit effort="100" lower="-1.5707963267948966" upper="1.5707963267948966" velocity="5"/>
  </joint>
  <link name="body1">
    <visual>
      <geometry>
        <box size="4.6 3.7 1.6"/>
      </geometry>
      <origin rpy="0 0 0" xyz="4.1 0 0"/>
      <material name="blue"/>
    </visual>
  </link>
  <joint name="body2_to_body1" type="revolute">
    <parent link="body1"/>
    <child link="body2"/>
    <origin rpy="0 0 0" xyz="8.2 0 0"/>
    <axis xyz="0 0 1"/>
    <limit effort="100" lower="-1.5707963267948966" upper="1.5707963267948966" velocity="5"/>
  </joint>
  <link name="body2">
    <visual>
      <geometry>
        <box size="4.6 1.4 3.3"/>
      </geometry>
      <origin rpy="0 0 0" xyz="4.1 0 0"/>
      <material name="blue"/>
    </visual>
  </link>
  <joint name="body3_to_body2" type="revolute">
    <parent link="body2"/>
    <child link="body3"/>
    <origin rpy="0 0 0" xyz="8.2 0 0"/>
    <axis xyz="0 1 0"/>
    <limit effort="100" lower="-1.5707963267948966" upper="1.5707963267948966" velocity="5"/>
  </joint>
  <link name="body3">
    <visual>
      <geometry>
        <box size="4.6 3.4 1.16"/>
      </geometry>
      <origin rpy="0 0 0" xyz="4.1 0 0"/>
      <material name="blue"/>
    </visual>
  </link>
</robot>

