<?xml version="1.0" ?>
<!-- =================================================================================== -->
<!-- |    This document was autogenerated by xacro from tri-snake.xacro                | -->
<!-- |    EDITING THIS FILE BY HAND IS NOT RECOMMENDED                                 | -->
<!-- =================================================================================== -->
<robot name="tri-snake" xmlns:xacro="http://www.ros.org/wiki/xacro">
  <material name="blue">
    <color rgba="0 0 0.8 0.7"/>
  </material>
  <material name="green">
    <color rgba="0 0.8 0 0.7"/>
  </material>
  <link name="base">
    <visual>
      <geometry>
        <box size="6 5 2.6"/>
      </geometry>
      <material name="green"/>
    </visual>
  </link>
  <!-- First chain -->
  <joint name="body1_to_base" type="revolute">
    <parent link="base"/>
    <child link="body1"/>
    <origin rpy="0 0 0" xyz="5.5 0 0"/>
    <axis xyz="0 1 0"/>
    <limit effort="100" lower="-1.57079632679" upper="1.57079632679" velocity="5"/>
  </joint>
  <link name="body1">
    <visual>
      <geometry>
        <box size="4.6 3.7 1.6"/>
      </geometry>
      <origin rpy="0 0 0" xyz="4.1 0 0"/>
      <material name="blue"/>
    </visual>
  </link>
  <joint name="body2_to_body1" type="revolute">
    <parent link="body1"/>
    <child link="body2"/>
    <origin rpy="0 0 0" xyz="8.2 0 0"/>
    <axis xyz="0 0 1"/>
    <limit effort="100" lower="-1.57079632679" upper="1.57079632679" velocity="5"/>
  </joint>
  <link name="body2">
    <visual>
      <geometry>
        <box size="4.6 1.4 3.3"/>
      </geometry>
      <origin rpy="0 0 0" xyz="4.1 0 0"/>
      <material name="blue"/>
    </visual>
  </link>
  <joint name="body3_to_body2" type="revolute">
    <parent link="body2"/>
    <child link="body3"/>
    <origin rpy="0 0 0" xyz="8.2 0 0"/>
    <axis xyz="0 1 0"/>
    <limit effort="100" lower="-1.57079632679" upper="1.57079632679" velocity="5"/>
  </joint>
  <link name="body3">
    <visual>
      <geometry>
        <box size="4.6 3.4 1.16"/>
      </geometry>
      <origin rpy="0 0 0" xyz="4.1 0 0"/>
      <material name="blue"/>
    </visual>
  </link>
  <!-- Second chain -->
  <joint name="body4_to_base" type="revolute">
    <parent link="base"/>
    <child link="body4"/>
    <origin rpy="0 0 0" xyz="-5.5 0 0"/>
    <axis xyz="0 1 0"/>
    <limit effort="100" lower="-1.57079632679" upper="1.57079632679" velocity="5"/>
  </joint>
  <link name="body4">
    <visual>
      <geometry>
        <box size="4.6 2.27 1.4"/>
      </geometry>
      <origin rpy="0 0 0" xyz="-4.1 0 0"/>
      <material name="blue"/>
    </visual>
  </link>
  <joint name="body5_to_body4" type="revolute">
    <parent link="body4"/>
    <child link="body5"/>
    <origin rpy="0 0 0" xyz="-8.2 0 0"/>
    <axis xyz="0 0 1"/>
    <limit effort="100" lower="-1.57079632679" upper="1.57079632679" velocity="5"/>
  </joint>
  <link name="body5">
    <visual>
      <geometry>
        <box size="4.6 1.7 2.4"/>
      </geometry>
      <origin rpy="0 0 0" xyz="-4.1 0 0"/>
      <material name="blue"/>
    </visual>
  </link>
  <joint name="body6_to_body5" type="revolute">
    <parent link="body5"/>
    <child link="body6"/>
    <origin rpy="0 0 0" xyz="-8.2 0 0"/>
    <axis xyz="0 1 0"/>
    <limit effort="100" lower="-1.57079632679" upper="1.57079632679" velocity="5"/>
  </joint>
  <link name="body6">
    <visual>
      <geometry>
        <box size="4.6 2.7 1.4"/>
      </geometry>
      <origin rpy="0 0 0" xyz="-4.1 0 0"/>
      <material name="blue"/>
    </visual>
  </link>
  <!-- Third chain -->
  <joint name="body7_to_base" type="revolute">
    <parent link="base"/>
    <child link="body7"/>
    <origin rpy="0 0 0" xyz="0 0 2.1"/>
    <axis xyz="1 0 0"/>
    <limit effort="100" lower="-1.57079632679" upper="1.57079632679" velocity="5"/>
  </joint>
  <link name="body7">
    <visual>
      <geometry>
        <box size="3.5 2.7 4.6"/>
      </geometry>
      <origin rpy="0 0 0" xyz="0 0 4.1 "/>
      <material name="blue"/>
    </visual>
  </link>
  <joint name="body8_to_body7" type="revolute">
    <parent link="body7"/>
    <child link="body8"/>
    <origin rpy="0 0 0" xyz="0 0 8.2"/>
    <axis xyz="0 1 0"/>
    <limit effort="100" lower="-1.57079632679" upper="1.57079632679" velocity="5"/>
  </joint>
  <link name="body8">
    <visual>
      <geometry>
        <box size="1.2 2.7 4.6"/>
      </geometry>
      <origin rpy="0 0 0" xyz="0 0 4.1"/>
      <material name="blue"/>
    </visual>
  </link>
  <joint name="body9_to_body8" type="revolute">
    <parent link="body8"/>
    <child link="body9"/>
    <origin rpy="0 0 0" xyz="0 0 8.2"/>
    <axis xyz="1 0 0"/>
    <limit effort="100" lower="-1.57079632679" upper="1.57079632679" velocity="5"/>
  </joint>
  <link name="body9">
    <visual>
      <geometry>
        <box size="3.5 2.7 4.6"/>
      </geometry>
      <origin rpy="0 0 0" xyz="0 0 4.1"/>
      <material name="blue"/>
    </visual>
  </link>
</robot>

